‚ùå Error loading model: Failed to import diffusers.pipelines.stable_diffusion_xl.pipeline_stable_diffusion_xl because of the following error (look up to see its traceback):
Failed to import diffusers.loaders.single_file because of the following error (look up to see its traceback):
module 'torch' has no attribute 'float8_e4m3fn'
Traceback (most recent call last):
  File "/Users/gabe/CUSTOMML/sdxl_env/lib/python3.10/site-packages/diffusers/utils/import_utils.py", line 820, in _get_module
    return importlib.import_module("." + module_name, self.__name__)
  File "/opt/homebrew/Cellar/python@3.10/3.10.17/Frameworks/Python.framework/Versions/3.10/lib/python3.10/importlib/__init__.py", line 126, in import_module
    return _bootstrap._gcd_import(name[level:], package, level)
  File "<frozen importlib._bootstrap>", line 1050, in _gcd_import
  File "<frozen importlib._bootstrap>", line 1027, in _find_and_load
  File "<frozen importlib._bootstrap>", line 1006, in _find_and_load_unlocked
  File "<frozen importlib._bootstrap>", line 688, in _load_unlocked
  File "<frozen importlib._bootstrap_external>", line 883, in exec_module
  File "<frozen importlib._bootstrap>", line 241, in _call_with_frames_removed
  File "/Users/gabe/CUSTOMML/sdxl_env/lib/python3.10/site-packages/diffusers/loaders/single_file.py", line 25, in <module>
    from .single_file_utils import (
  File "/Users/gabe/CUSTOMML/sdxl_env/lib/python3.10/site-packages/diffusers/loaders/single_file_utils.py", line 28, in <module>
    from ..models.modeling_utils import load_state_dict
  File "/Users/gabe/CUSTOMML/sdxl_env/lib/python3.10/site-packages/diffusers/models/modeling_utils.py", line 40, in <module>
    from ..quantizers import DiffusersAutoQuantizer, DiffusersQuantizer
  File "/Users/gabe/CUSTOMML/sdxl_env/lib/python3.10/site-packages/diffusers/quantizers/__init__.py", line 15, in <module>
    from .auto import DiffusersAutoQuantizer
  File "/Users/gabe/CUSTOMML/sdxl_env/lib/python3.10/site-packages/diffusers/quantizers/auto.py", line 33, in <module>
    from .torchao import TorchAoHfQuantizer
  File "/Users/gabe/CUSTOMML/sdxl_env/lib/python3.10/site-packages/diffusers/quantizers/torchao/__init__.py", line 15, in <module>
    from .torchao_quantizer import TorchAoHfQuantizer
  File "/Users/gabe/CUSTOMML/sdxl_env/lib/python3.10/site-packages/diffusers/quantizers/torchao/torchao_quantizer.py", line 64, in <module>
    torch.float8_e4m3fn,
AttributeError: module 'torch' has no attribute 'float8_e4m3fn'

The above exception was the direct cause of the following exception:

Traceback (most recent call last):
  File "/Users/gabe/CUSTOMML/sdxl_env/lib/python3.10/site-packages/diffusers/utils/import_utils.py", line 820, in _get_module
    return importlib.import_module("." + module_name, self.__name__)
  File "/opt/homebrew/Cellar/python@3.10/3.10.17/Frameworks/Python.framework/Versions/3.10/lib/python3.10/importlib/__init__.py", line 126, in import_module
    return _bootstrap._gcd_import(name[level:], package, level)
  File "<frozen importlib._bootstrap>", line 1050, in _gcd_import
  File "<frozen importlib._bootstrap>", line 1027, in _find_and_load
  File "<frozen importlib._bootstrap>", line 1006, in _find_and_load_unlocked
  File "<frozen importlib._bootstrap>", line 688, in _load_unlocked
  File "<frozen importlib._bootstrap_external>", line 883, in exec_module
  File "<frozen importlib._bootstrap>", line 241, in _call_with_frames_removed
  File "/Users/gabe/CUSTOMML/sdxl_env/lib/python3.10/site-packages/diffusers/pipelines/stable_diffusion_xl/pipeline_stable_diffusion_xl.py", line 29, in <module>
    from ...loaders import (
  File "<frozen importlib._bootstrap>", line 1075, in _handle_fromlist
  File "/Users/gabe/CUSTOMML/sdxl_env/lib/python3.10/site-packages/diffusers/utils/import_utils.py", line 810, in __getattr__
    module = self._get_module(self._class_to_module[name])
  File "/Users/gabe/CUSTOMML/sdxl_env/lib/python3.10/site-packages/diffusers/utils/import_utils.py", line 822, in _get_module
    raise RuntimeError(
RuntimeError: Failed to import diffusers.loaders.single_file because of the following error (look up to see its traceback):
module 'torch' has no attribute 'float8_e4m3fn'

The above exception was the direct cause of the following exception:

Traceback (most recent call last):
  File "/Users/gabe/CUSTOMML/basic_app.py", line 227, in load_sdxl_model_thread
    from diffusers import StableDiffusionXLPipeline
  File "<frozen importlib._bootstrap>", line 1075, in _handle_fromlist
  File "/Users/gabe/CUSTOMML/sdxl_env/lib/python3.10/site-packages/diffusers/utils/import_utils.py", line 811, in __getattr__
    value = getattr(module, name)
  File "/Users/gabe/CUSTOMML/sdxl_env/lib/python3.10/site-packages/diffusers/utils/import_utils.py", line 811, in __getattr__
    value = getattr(module, name)
  File "/Users/gabe/CUSTOMML/sdxl_env/lib/python3.10/site-packages/diffusers/utils/import_utils.py", line 810, in __getattr__
    module = self._get_module(self._class_to_module[name])
  File "/Users/gabe/CUSTOMML/sdxl_env/lib/python3.10/site-packages/diffusers/utils/import_utils.py", line 822, in _get_module
    raise RuntimeError(
RuntimeError: Failed to import diffusers.pipelines.stable_diffusion_xl.pipeline_stable_diffusion_xl because of the following error (look up to see its traceback):
Failed to import diffusers.loaders.single_file because of the following error (look up to see its traceback):
module 'torch' has no attribute 'float8_e4m3fn'